2024-01-31 16:39:00,407 INFO    StreamThr :26272 [internal.py:wandb_internal():86] W&B internal server running at pid: 26272, started at: 2024-01-31 16:39:00.405977
2024-01-31 16:39:00,408 DEBUG   HandlerThread:26272 [handler.py:handle_request():146] handle_request: status
2024-01-31 16:39:00,419 INFO    WriterThread:26272 [datastore.py:open_for_write():85] open: D:\Source_Code_Work\TTA_MFD\wandb\run-20240131_163900-gm6pn985\run-gm6pn985.wandb
2024-01-31 16:39:00,420 DEBUG   SenderThread:26272 [sender.py:send():380] send: header
2024-01-31 16:39:00,423 DEBUG   SenderThread:26272 [sender.py:send():380] send: run
2024-01-31 16:39:04,149 INFO    SenderThread:26272 [retry.py:__call__():172] Retry attempt failed:
Traceback (most recent call last):
  File "D:\P\anaconda\envs\pytorch\lib\site-packages\urllib3\connectionpool.py", line 700, in urlopen
    self._prepare_proxy(conn)
  File "D:\P\anaconda\envs\pytorch\lib\site-packages\urllib3\connectionpool.py", line 994, in _prepare_proxy
    conn.connect()
  File "D:\P\anaconda\envs\pytorch\lib\site-packages\urllib3\connection.py", line 364, in connect
    self.sock = conn = self._connect_tls_proxy(hostname, conn)
  File "D:\P\anaconda\envs\pytorch\lib\site-packages\urllib3\connection.py", line 499, in _connect_tls_proxy
    socket = ssl_wrap_socket(
  File "D:\P\anaconda\envs\pytorch\lib\site-packages\urllib3\util\ssl_.py", line 453, in ssl_wrap_socket
    ssl_sock = _ssl_wrap_socket_impl(sock, context, tls_in_tls)
  File "D:\P\anaconda\envs\pytorch\lib\site-packages\urllib3\util\ssl_.py", line 495, in _ssl_wrap_socket_impl
    return ssl_context.wrap_socket(sock)
  File "D:\P\anaconda\envs\pytorch\lib\ssl.py", line 500, in wrap_socket
    return self.sslsocket_class._create(
  File "D:\P\anaconda\envs\pytorch\lib\ssl.py", line 1040, in _create
    self.do_handshake()
  File "D:\P\anaconda\envs\pytorch\lib\ssl.py", line 1309, in do_handshake
    self._sslobj.do_handshake()
ssl.SSLEOFError: EOF occurred in violation of protocol (_ssl.c:1131)

During handling of the above exception, another exception occurred:

Traceback (most recent call last):
  File "D:\P\anaconda\envs\pytorch\lib\site-packages\requests\adapters.py", line 489, in send
    resp = conn.urlopen(
  File "D:\P\anaconda\envs\pytorch\lib\site-packages\urllib3\connectionpool.py", line 785, in urlopen
    retries = retries.increment(
  File "D:\P\anaconda\envs\pytorch\lib\site-packages\urllib3\util\retry.py", line 592, in increment
    raise MaxRetryError(_pool, url, error or ResponseError(cause))
urllib3.exceptions.MaxRetryError: HTTPSConnectionPool(host='api.wandb.ai', port=443): Max retries exceeded with url: /graphql (Caused by SSLError(SSLEOFError(8, 'EOF occurred in violation of protocol (_ssl.c:1131)')))

During handling of the above exception, another exception occurred:

Traceback (most recent call last):
  File "D:\P\anaconda\envs\pytorch\lib\site-packages\wandb\sdk\lib\retry.py", line 131, in __call__
    result = self._call_fn(*args, **kwargs)
  File "D:\P\anaconda\envs\pytorch\lib\site-packages\wandb\sdk\internal\internal_api.py", line 366, in execute
    return self.client.execute(*args, **kwargs)  # type: ignore
  File "D:\P\anaconda\envs\pytorch\lib\site-packages\wandb\vendor\gql-0.2.0\wandb_gql\client.py", line 52, in execute
    result = self._get_result(document, *args, **kwargs)
  File "D:\P\anaconda\envs\pytorch\lib\site-packages\wandb\vendor\gql-0.2.0\wandb_gql\client.py", line 60, in _get_result
    return self.transport.execute(document, *args, **kwargs)
  File "D:\P\anaconda\envs\pytorch\lib\site-packages\wandb\sdk\lib\gql_request.py", line 58, in execute
    request = self.session.post(self.url, **post_args)
  File "D:\P\anaconda\envs\pytorch\lib\site-packages\requests\sessions.py", line 635, in post
    return self.request("POST", url, data=data, json=json, **kwargs)
  File "D:\P\anaconda\envs\pytorch\lib\site-packages\requests\sessions.py", line 587, in request
    resp = self.send(prep, **send_kwargs)
  File "D:\P\anaconda\envs\pytorch\lib\site-packages\requests\sessions.py", line 701, in send
    r = adapter.send(request, **kwargs)
  File "D:\P\anaconda\envs\pytorch\lib\site-packages\requests\adapters.py", line 563, in send
    raise SSLError(e, request=request)
requests.exceptions.SSLError: HTTPSConnectionPool(host='api.wandb.ai', port=443): Max retries exceeded with url: /graphql (Caused by SSLError(SSLEOFError(8, 'EOF occurred in violation of protocol (_ssl.c:1131)')))
2024-01-31 16:39:05,451 DEBUG   HandlerThread:26272 [handler.py:handle_request():146] handle_request: keepalive
2024-01-31 16:39:10,491 DEBUG   HandlerThread:26272 [handler.py:handle_request():146] handle_request: keepalive
2024-01-31 16:39:16,565 INFO    MainThread:26272 [internal.py:handle_exit():76] Internal process exited
